Input_Data/rock_data.csv
Artist,Genre,key,mode,valence,tempo,year,speechiness,instrumentalness,time_signature
David Bowie,Rock,G,Major,0.607,115.007,2018.0,0.049,0.0252,4.0
Tori Amos,Rock,A,Major,0.445,143.972,2003.0,0.0489,0.0,4.0
R.E.M.,Rock,C,Major,0.391,116.752,2007.0,0.0262,0.0027,4.0
My Chemical Romance,Rock,E,Minor,0.241,110.984,2011.0,0.0374,0.0,4.0
Gram Parsons,Rock,C#,Major,0.239,77.815,2018.0,0.0243,0.00035,4.0
Jimi Hendrix,Rock,C,Major,0.738,120.949,2018.0,0.0397,0.431,4.0
Cowboy Junkies,Rock,G,Major,0.406,142.52200000000005,1990.0,0.0305,0.0006309999999999999,4.0
Cowboy Junkies,Rock,G,Major,0.133,149.032,1995.0,0.0323,0.344,4.0
Sonic Youth,Rock,E,Minor,0.244,95.686,2020.0,0.06,0.013,4.0
Bob Dylan,Rock,G#,Major,0.15,112.692,2008.0,0.0347,0.0007639999999999999,4.0
Third Day,Rock,A,Major,0.5489999999999999,184.08,2004.0,0.0682,2.12e-05,4.0
Rod Stewart,Rock,F#,Minor,0.306,92.657,2003.0,0.0396,5.37e-06,4.0
Whitesnake,Rock,A,Major,0.322,138.112,2018.0,0.0264,0.0133,4.0
David Bowie,Rock,F,Major,0.466,132.04,2016.0,0.115,0.0578,4.0
Tori Amos,Rock,A#,Minor,0.16699999999999998,128.989,2019.0,0.0306,5.69e-05,4.0
Arcade Fire,Rock,G,Major,0.836,79.53699999999998,2007.0,0.0436,0.0015,4.0
Heart,Rock,A,Major,0.485,102.923,1983.0,0.0386,0.000656,4.0
Santana,Rock,E,Minor,0.8440000000000001,126.709,1999.0,0.0683,0.0324,4.0
Weezer,Rock,D#,Major,0.38,128.079,2016.0,0.0368,0.0,4.0
Fleetwood Mac,Rock,A#,Major,0.8809999999999999,131.529,1973.0,0.0293,0.389,4.0
Joan Jett & The Blackhearts,Rock,B,Major,0.66,135.407,2010.0,0.107,5.23e-05,4.0
Rod Stewart,Rock,F,Minor,0.217,114.732,1977.0,0.033,0.000118,4.0
Noel Gallagher,Rock,E,Minor,0.27,121.492,2009.0,0.0326,0.00703,4.0
The Flaming Lips,Rock,A,Major,0.238,79.509,2007.0,0.0296,0.00804,4.0
Elvis Presley,Rock,C,Major,0.922,87.98700000000002,1957.0,0.171,0.0,4.0
ZZ Top,Rock,B,Minor,0.397,105.054,1999.0,0.0397,0.008140000000000001,4.0
Elvis Presley,Rock,C,Major,0.917,99.887,1972.0,0.0362,0.312,4.0
Elvis Presley,Rock,C,Major,0.765,77.675,1957.0,0.0367,0.0,4.0
Elvis Presley,Rock,G,Major,0.933,104.904,1963.0,0.0296,0.0121,4.0
Drive,Rock,F#,Minor,0.267,142.842,2019.0,0.0785,0.000111,4.0
Radiohead,Rock,A,Major,0.375,172.851,1995.0,0.0344,0.261,3.0
Alice Cooper,Rock,C,Major,0.6559999999999999,124.138,1977.0,0.0326,5.55e-06,4.0
Elvis Presley,Rock,C,Major,0.601,128.751,1959.0,0.0709,0.000179,4.0
Van Halen,Rock,C#,Minor,0.5,128.289,1982.0,0.0708,1.68e-06,4.0
Van Halen,Rock,G#,Major,0.652,124.982,2015.0,0.055,0.446,4.0
ZZ Top,Rock,D,Major,0.847,98.222,2019.0,0.041,0.013,4.0
Elvis Presley,Rock,C,Major,0.246,170.22,2007.0,0.0306,1.81e-06,3.0
Elvis Presley,Rock,C,Major,0.282,62.81800000000001,1997.0,0.0304,1.45e-06,3.0
Elvis Presley,Rock,D#,Major,0.972,116.338,1963.0,0.0599,0.0,4.0
LCD Soundsystem,Rock,A,Minor,0.964,150.744,2018.0,0.0933,0.114,4.0
311,Rock,D,Major,0.784,105.551,1999.0,0.0282,1.42e-05,4.0
Cowboy Junkies,Rock,C#,Minor,0.29100000000000004,109.95,2020.0,0.0461,0.5579999999999999,4.0
The Doors,Rock,A,Major,0.261,104.45,2019.0,0.0527,8.48e-06,4.0
Elvis Presley,Rock,F,Major,0.8909999999999999,122.527,1968.0,0.116,0.00141,4.0
Elvis Presley,Rock,F,Major,0.888,122.583,2007.0,0.157,2.2e-05,4.0
Bruce Springsteen,Rock,C,Major,0.532,179.597,2018.0,0.157,0.0,4.0
Slipknot,Rock,G,Major,0.267,96.325,2012.0,0.124,0.00128,4.0
Slipknot,Rock,F#,Major,0.116,103.37,2012.0,0.19,0.57,4.0
Slipknot,Rock,G,Major,0.35,94.528,2009.0,0.107,0.72,4.0
The Flaming Lips,Rock,G,Major,0.195,116.689,1993.0,0.0365,0.000717,4.0
Metallica,Rock,E,Minor,0.967,146.724,1988.0,0.0369,0.909,4.0
Metallica,Rock,A,Major,0.0475,173.801,1988.0,0.215,0.574,4.0
Metallica,Rock,E,Minor,0.424,173.583,1988.0,0.183,0.147,4.0
Jimi Hendrix,Rock,F#,Major,0.0298,101.152,1968.0,0.282,0.271,4.0
Pato Fu,Rock,A,Major,0.907,122.119,1996.0,0.0298,0.16899999999999998,4.0
Tori Amos,Rock,A#,Major,0.227,135.873,2000.0,0.0293,6.459999999999997e-05,4.0
Tori Amos,Rock,A#,Major,0.13699999999999998,135.94,2007.0,0.0359,0.0242,4.0
Tori Amos,Rock,A#,Major,0.207,135.989,2007.0,0.0335,0.00557,4.0
Pearl Jam,Rock,A,Minor,0.265,151.592,2002.0,0.0916,7.43e-05,4.0
Scorpions,Rock,F#,Major,0.743,170.571,1999.0,0.036000000000000004,0.0713,4.0
Alice Cooper,Rock,A,Major,0.257,125.952,1969.0,0.403,0.0,4.0
Alice Cooper,Rock,C,Major,0.158,125.812,1992.0,0.105,0.011,4.0
The Flaming Lips,Rock,G,Major,0.17800000000000002,120.409,2018.0,0.0301,0.00569,4.0
The Cure,Rock,D,Minor,0.467,174.97400000000005,2011.0,0.0352,0.135,4.0
The Cure,Rock,C,Major,0.355,174.701,1979.0,0.0981,0.0264,4.0
The Cure,Rock,D,Minor,0.541,162.954,1979.0,0.0283,0.413,4.0
The Cure,Rock,A,Minor,0.0831,112.67,1979.0,0.13699999999999998,0.918,4.0
The Cure,Rock,A,Minor,0.173,122.026,1979.0,0.0385,0.8370000000000001,4.0
Incubus,Rock,C,Major,0.297,153.976,2001.0,0.0314,0.5770000000000001,4.0
The Strokes,Rock,E,Major,0.591,145.056,2003.0,0.0379,0.8,4.0
The Strokes,Rock,D,Major,0.394,82.95700000000002,2006.0,0.0411,0.0383,3.0
Radiohead,Rock,C#,Major,0.8440000000000001,94.458,2007.0,0.0422,0.338,4.0
Skid Row,Rock,C#,Minor,0.354,90.439,2017.0,0.0298,7.26e-05,4.0
A Day To Remember,Rock,F,Major,0.239,156.447,2005.0,0.308,0.0816,4.0
Patti Smith,Rock,B,Minor,0.799,133.387,1997.0,0.0278,0.313,4.0
Alejandro Escovedo,Rock,C,Major,0.232,91.543,2009.0,0.0279,0.0,3.0
Cheap Trick,Rock,F#,Major,0.777,138.336,1977.0,0.875,9.11e-06,3.0
Jimi Hendrix,Rock,C#,Major,0.229,138.25799999999998,1968.0,0.106,0.00609,4.0
Van Halen,Rock,E,Major,0.0697,68.84,1984.0,0.0378,7.72e-05,3.0
Radiohead,Rock,F,Minor,0.386,149.582,2003.0,0.0504,5.1e-05,4.0
Radiohead,Rock,F,Minor,0.34700000000000003,148.165,2004.0,0.0561,0.0007559999999999999,4.0
Pato Fu,Rock,G,Major,0.931,165.123,2001.0,0.0481,0.000453,4.0
Pearl Jam,Rock,A,Major,0.328,199.979,1991.0,0.0535,0.262,3.0
The Vaccines,Rock,C,Major,0.425,168.1,2015.0,0.174,0.0006580000000000001,4.0
Cowboy Junkies,Rock,C,Major,0.131,71.445,1988.0,0.0344,0.00824,4.0
Cowboy Junkies,Rock,C,Major,0.0882,82.17399999999998,1995.0,0.0303,0.35,4.0
Green Day,Rock,A#,Major,0.6659999999999999,187.433,2017.0,0.13,8.070000000000001e-05,4.0
Arctic Monkeys,Rock,G,Major,0.618,157.001,2013.0,0.0514,2.58e-05,4.0
Vampire Weekend,Rock,C,Major,0.449,73.785,2019.0,0.0427,0.00105,4.0
Green Day,Rock,F,Major,0.419,159.072,2009.0,0.0364,0.0,4.0
Green Day,Rock,F,Major,0.445,167.895,2009.0,0.0411,0.000134,4.0
Rush,Rock,A,Minor,0.275,132.025,2011.0,0.107,0.00132,4.0
Green Day,Rock,C#,Major,0.0953,119.491,2009.0,0.189,0.00943,4.0
Ozzy Osbourne,Rock,C#,Major,0.486,110.513,2005.0,0.0844,0.00845,4.0
Wilco,Rock,C,Minor,0.0,0.0,2020.0,0.0,0.0,0.0
Stevie Nicks,Rock,A,Minor,0.695,123.015,2014.0,0.0283,0.000443,4.0
The Black Keys,Rock,B,Minor,0.171,212.509,2002.0,0.722,0.135,4.0
Patti Smith,Rock,A,Major,0.605,119.18,1978.0,0.0553,0.0,4.0
Paramore,Rock,D,Major,0.409,90.00399999999998,2017.0,0.0266,3.5600000000000005e-05,4.0
Incubus,Rock,B,Minor,0.306,117.431,2004.0,0.0425,0.8079999999999999,4.0
The Lemonheads,Rock,D,Major,0.6759999999999999,181.034,1987.0,0.0377,0.0476,4.0
Cheap Trick,Rock,E,Major,0.7909999999999999,141.459,1983.0,0.0411,4.55e-05,4.0
Chuck Berry,Rock,C,Major,0.847,171.665,2017.0,0.204,0.0015,3.0
Stone Sour,Rock,B,Minor,0.338,163.919,2019.0,0.134,0.00863,4.0
Van Halen,Rock,D,Major,0.21600000000000005,119.166,1991.0,0.0432,0.67,3.0
Van Halen,Rock,A,Major,0.248,122.395,1993.0,0.0909,0.865,3.0
Bob Dylan,Rock,B,Major,0.852,91.121,2008.0,0.0457,1.94e-05,4.0
ZZ Top,Rock,A#,Major,0.677,96.061,1999.0,0.0515,0.0601,4.0
Tenacious D,Rock,G,Major,0.348,107.003,2012.0,0.03,4.41e-06,4.0
The Cure,Rock,C#,Minor,0.265,89.995,2000.0,0.041,0.00891,4.0
Tenacious D,Rock,G,Major,0.29100000000000004,123.32,2016.0,0.0472,0.0,4.0
The Lemonheads,Rock,G,Major,0.57,196.343,2014.0,0.0938,0.00093,4.0
Matchbox Twenty,Rock,G#,Major,0.5429999999999999,108.031,1996.0,0.0284,0.0,4.0
Matchbox Twenty,Rock,G#,Major,0.5429999999999999,108.031,2018.0,0.0284,0.0,4.0
Cowboy Junkies,Rock,D,Minor,0.222,94.176,2011.0,0.0277,0.0428,4.0
Incubus,Rock,E,Minor,0.036000000000000004,118.954,2004.0,0.0407,0.847,4.0
Radiohead,Rock,A,Major,0.225,124.157,2007.0,0.0311,0.0657,4.0
