Output_Data/rock_word_count.csv
words,0
.,434313
the,218337
",",213733
you,183442
i,179032
to,127077
and,116896
a,104090
me,86518
in,69462
my,67095
it,64986
of,61518
your,53945
on,47609
all,45706
that,44316
i'm,43276
is,42201
for,37555
be,37212
we,36037
don't,33658
so,32856
it's,30608
love,30229
know,29518
but,29075
?,28613
no,27717
just,27102
this,27093
with,26049
like,25514
what,25458
oh,25205
can,23897
when,23873
now,22943
up,22869
do,22389
out,21150
you're,20936
are,20606
down,20351
time,20193
got,19733
if,19251
one,19249
go,19143
never,18948
will,18460
get,18363
see,17525
not,17406
want,16975
was,15999
can't,15812
have,15426
come,15036
yeah,14827
take,14770
from,14701
they,14505
way,14187
she,14098
away,14069
!,13677
say,13674
let,13301
back,13010
feel,12550
i'll,12495
at,12416
as,12391
gonna,12342
there,12113
make,12073
life,12020
baby,11278
i've,11238
here,11230
her,10902
how,10407
night,10047
he,9868
day,9844
more,9790
been,9779
where,9768
could,9726
need,9634
world,9580
there's,9529
right,9511
heart,9384
by,9357
again,9223
tell,9083
only,8973
too,8758
well,8689
our,8678
give,8391
through,8177
think,8162
eyes,8059
why,8049
who,7698
man,7693
won't,7652
around,7642
or,7605
little,7446
'cause,7363
long,7292
am,7288
find,7267
good,7245
some,7219
we're,7201
us,7061
still,7037
about,7025
over,6961
wanna,6940
said,6921
nothing,6745
mind,6729
that's,6702
home,6689
then,6675
look,6653
keep,6649
every,6581
always,6343
were,6332
hey,6196
had,6157
ever,6115
would,6060
into,6012
his,5889
inside,5885
ain't,5828
things,5721
she's,5687
alone,5681
girl,5601
hear,5577
an,5547
gone,5455
light,5441
everything,5309
live,5293
believe,5288
much,5241
hold,5168
better,5106
run,5099
try,5045
you've,5035
something,5021
them,4955
before,4922
tonight,4894
another,4871
face,4850
you'll,4717
leave,4685
turn,4634
really,4573
going,4565
left,4550
off,4488
end,4485
head,4479
than,4418
gotta,4399
lost,4379
has,4366
last,4291
did,4250
place,4247
sun,4226
stay,4218
fall,4191
la,4187
die,4171
these,4135
made,4041
thing,4040
please,4037
chorus,3975
hard,3927
their,3923
new,3906
dream,3878
show,3872
call,3848
same,3842
cause,3825
break,3790
people,3786
without,3782
stop,3768
wrong,3760
i'd,3724
free,3705
fire,3698
old,3687
soul,3642
change,3631
coming,3630
own,3601
hand,3575
put,3544
walk,3489
pain,3477
s,3453
god,3440
even,3440
waiting,3425
him,3386
should,3378
myself,3336
far,3325
name,3313
we'll,3294
mine,3226
care,3216
enough,3185
rock,3157
comes,3139
yes,3138
someone,3133
sky,3122
stand,3119
feeling,3116
cry,3115
he's,3089
na,3052
bad,3039
high,3008
days,2997
looking,2978
remember,2921
what's,2890
words,2889
play,2876
sweet,2869
maybe,2850
thought,2849
yourself,2835
dead,2832
hands,2828
must,2825
other,2820
forever,2815
song,2810
those,2797
sing,2786
ooh,2779
let's,2774
living,2748
cold,2747
true,2739
two,2737
alive,2730
help,2724
because,2718
real,2706
while,2703
they're,2695
dreams,2683
wish,2682
wait,2664
together,2651
side,2649
fight,2645
done,2642
found,2632
t,2631
hope,2626
alright,2594
lonely,2544
dance,2522
lose,2514
big,2504
times,2500
behind,2476
blue,2463
black,2461
open,2457
rain,2450
start,2444
lie,2439
today,2434
bring,2430
dark,2418
talk,2418
line,2392
watch,2381
once,2373
makes,2372
best,2364
any,2359
door,2357
close,2351
goes,2345
ya,2339
its,2331
knows,2330
hell,2315
everybody,2315
broken,2310
boy,2298
town,2298
many,2276
hate,2267
friend,2263
roll,2248
didn't,2246
knew,2241
seen,2228
told,2223
sometimes,2223
getting,2217
ah,2196
hide,2195
easy,2195
running,2193
came,2189
save,2183
until,2168
might,2162
money,2151
lies,2145
goodbye,2130
anything,2128
used,2116
truth,2104
kiss,2104
fear,2102
we've,2102
move,2096
sleep,2094
falling,2076
trying,2061
late,2057
ground,2056
till,2048
forget,2028
under,2001
sound,1984
fly,1983
blood,1973
friends,1969
first,1967
ready,1965
may,1962
burn,1955
else,1953
took,1951
understand,1939
after,1938
seems,1934
road,1929
tears,1913
morning,1909
city,1891
along,1887
crazy,1869
smile,1868
young,1866
wanted,1863
mean,1859
happy,1852
woman,1852
touch,1847
deep,1834
sure,1811
such,1805
ride,1796
everyone,1791
round,1789
set,1788
heard,1777
wind,1773
kind,1771
listen,1764
wake,1757
born,1750
nobody,1744
whoa,1739
matter,1735
feels,1734
saw,1731
kill,1728
though,1725
does,1724
years,1716
anymore,1715
hurt,1712
room,1706
fine,1703
tried,1695
wild,1687
chance,1687
m,1678
heaven,1671
ask,1668
reason,1645
tomorrow,1639
arms,1628
each,1619
doesn't,1614
control,1608
red,1603
stars,1592
lay,1588
you'd,1587
pretty,1583
miss,1577
wonder,1576
lights,1573
white,1571
past,1566
girls,1565
lord,1552
street,1545
fool,1524
sea,1523
shine,1521
soon,1521
honey,1517
burning,1502
somebody,1501
apart,1501
fuck,1495
gave,1493
beat,1490
guess,1484
death,1480
between,1473
fun,1472
part,1472
da,1465
music,1461
bed,1461
word,1455
whole,1453
strong,1440
beautiful,1439
re,1435
afraid,1434
very,1433
couldn't,1432
house,1425
next,1413
above,1412
who's,1399
war,1399
went,1397
work,1392
air,1391
fast,1386
gets,1382
full,1379
moon,1376
child,1367
game,1365
meet,1359
takes,1352
feet,1352
tired,1349
sick,1343
step,1340
water,1340
standing,1339
making,1339
blind,1331
taking,1322
rest,1320
shake,1318
voice,1316
land,1314
star,1314
pay,1311
wants,1301
lives,1292
5,1290
sad,1290
hit,1287
thinking,1283
walking,1282
cannot,1280
since,1271
follow,1270
somewhere,1270
boys,1267
e,1263
hot,1260
moment,1256
says,1250
upon,1248
body,1246
mother,1243
breathe,1241
o,1240
floor,1238
seem,1238
low,1233
rise,1232
eye,1229
calling,1224
hearts,1223
empty,1220
wall,1220
uh,1219
gun,1215
breath,1209
king,1208
3,1202
blame,1198
being,1197
skin,1195
learn,1192
children,1172
shame,1162
lot,1161
belong,1157
mama,1152
outside,1152
slow,1148
three,1146
cut,1144
'em,1142
power,1137
felt,1131
throw,1128
earth,1121
holding,1115
across,1106
peace,1097
use,1094
caught,1092
knees,1092
blow,1091
shit,1091
2,1082
wouldn't,1079
son,1076
sorry,1072
loved,1069
train,1064
nowhere,1063
loving,1060
reach,1046
turned,1044
river,1042
yet,1040
car,1040
summer,1039
future,1038
sit,1037
scream,1033
isn't,1033
doing,1023
turning,1018
tight,1018
drive,1016
drink,1015
d,1015
party,1014
faith,1013
singing,1004
carry,1003
;,1001
don,999
straight,992
story,990
keeps,989
7,987
ways,981
looks,980
bit,979
bright,977
meant,977
top,977
taste,974
clear,972
cool,966
watching,965
babe,964
giving,963
ones,963
dying,960
dear,953
mouth,952
talking,951
strange,950
gold,948
tear,945
anyone,943
fade,942
known,941
streets,938
yours,937
leaving,935
ba,935
both,934
pull,929
memories,928
pray,924
crying,922
hair,922
trust,922
catch,922
waste,921
great,919
breaking,915
lover,914
against,910
men,910
perfect,909
angel,907
higher,906
loves,906
nice,905
they'll,902
become,899
lady,898
losing,896
win,895
0,893
within,892
darkness,891
'til,889
lead,886
space,885
half,884
fell,877
near,876
blues,875
worth,874
pass,873
devil,872
speak,871
hello,867
silence,863
promise,861
nights,859
radio,858
read,856
which,852
started,847
someday,845
finally,843
kids,841
stone,841
pick,840
walls,839
answer,838
moving,836
lips,835
dirty,835
trouble,825
grow,825
fucking,823
send,821
goin',819
damn,819
almost,819
dreaming,817
called,814
memory,806
freedom,806
dog,802
hole,800
loud,799
needs,795
ll,793
bye,793
scared,788
closer,787
thoughts,787
hang,786
bleed,784
sight,782
dancing,782
saying,780
already,779
shut,779
met,779
four,778
shot,778
window,777
push,777
4,776
father,774
shadows,772
comin',772
second,772
most,771
different,770
anyway,765
thousand,765
christmas,764
miles,763
ocean,763
green,760
whatever,758
shout,754
lyrics,753
holy,753
pretend,751
human,751
luck,748
safe,745
cross,742
doubt,741
warm,741
she'll,737
insane,735
million,734
laugh,733
shoes,733
wide,731
jesus,730
gimme,728
beyond,726
fill,722
sense,722
begin,722
mad,719
repeat,719
looked,719
buy,718
bones,715
somehow,714
turns,712
evil,707
number,707
everywhere,706
point,704
'bout,704
'round,703
choose,702
everybody's,699
okay,698
edge,696
daddy,696
playing,696
yesterday,695
killing,695
taken,694
pride,694
darling,693
feelings,693
